<robot name="my_robot">
    <!-- Base Link -->
    <link name="base_link">
        <visual>
            <geometry>
                <box size="0.5 0.3 0.2"/>
            </geometry>
            <material name="blue"/>
        </visual>
        <collision>
            <geometry>
                <box size="0.5 0.3 0.2"/>
            </geometry>
        </collision>
        <inertial>
            <mass value="1.0"/>
            <origin xyz="0 0 0"/>
            <inertia ixx="0.01" ixy="0.0" ixz="0.0" iyy="0.01" iyz="0.0" izz="0.01"/>
        </inertial>
    </link>
    
    <!-- Left Wheel -->
    <link name="left_wheel">
        <visual>
            <geometry>
                <cylinder radius="0.05" length="0.02"/>
            </geometry>
            <material name="black"/>
        </visual>
    </link>
    
    <!-- Right Wheel -->
    <link name="right_wheel">
        <visual>
            <geometry>
                <cylinder radius="0.05" length="0.02"/>
            </geometry>
            <material name="black"/>
        </visual>
    </link>

    <!-- Joints -->
    <joint name="left_wheel_joint" type="continuous">
        <parent link="base_link"/>
        <child link="left_wheel"/>
        <origin xyz="-0.15 0 0" rpy="0 0 1.5708"/>
        <axis xyz="0 1 0"/>
    </joint>

    <joint name="right_wheel_joint" type="continuous">
        <parent link="base_link"/>
        <child link="right_wheel"/>
        <origin xyz="0.15 0 0" rpy="0 0 1.5708"/>
        <axis xyz="0 1 0"/>
    </joint>
    
    <!-- Proximity Sensor -->
    <link name="proximity_sensor_link">
        <visual>
            <geometry>
                <cylinder radius="0.02" length="0.05"/>
            </geometry>
            <material name="green"/>
        </visual>
        <origin xyz="0 0 0.1"/>
    </link>

    <joint name="proximity_sensor_joint" type="fixed">
        <parent link="base_link"/>
        <child link="proximity_sensor_link"/>
        <origin xyz="0 0 0.1"/>
    </joint>

    <!-- Proximity Sensor with Gazebo Plugin -->
    <gazebo>
        <sensor name="proximity_sensor" type="ray">
            <origin xyz="0 0 0.05" rpy="0 0 0"/>
            <update_rate>10</update_rate>
            <ray>
                <scan>
                    <horizontal>
                        <samples>20</samples>
                        <resolution>1</resolution>
                        <min_angle>-0.5</min_angle>
                        <max_angle>0.5</max_angle>
                    </horizontal>
                </scan>
                <range>
                    <min>0.02</min>
                    <max>3.0</max>
                    <resolution>0.01</resolution>
                </range>
            </ray>
        </sensor>
    </gazebo>
    
    <!-- Flash for Siren -->
    <link name="flash">
        <visual>
            <geometry>
                <sphere radius="0.02"/>
            </geometry>
            <material name="yellow"/>
        </visual>
        <origin xyz="0 0 0.15"/>
    </link>

    <joint name="flash_joint" type="fixed">
        <parent link="base_link"/>
        <child link="flash"/>
        <origin xyz="0 0 0.15"/>
    </joint>
</robot>

